Workbook
Name SiteListRange: SiteList!$A$1:INDEX(SiteList!$A:$A,COUNTA(SiteList!$A:$A))

Sheet Site Data Sheet
A2: DAKOTA COUNTY SITE DATA SHEET
A3: Surveyor(s):
A5: Revele Name:
A6: Purpose of releve: Classification, Site documentation, Rare species habitat, Monitoring
A9: Date:
A12: Ownership: | B12: Dakota County
A13: Vegetation:
A14: Site:
A15: Native Plant Community Class:
A16: NPC Type/subtype (optional):
A18: Community Ranking in Releve:
A19: Stand Typical of Community:
A20: if No, identify appropriate modifier:
A21: Plot Location:
A24: LOCATION INFORMATION
A28: Latitude:
A29: Longitude:
A36: Permanent Marker:
... A41: Elevation: _____ ft
A42: Slope: ______ ° | B42: or ____ %
A43: Aspect: _____° (degree)
A44: Topographic Context:
A45: SOIL INFORMATION
A53: Litter Type:
A54: Litter Thickness: cm
A55: Drainage Class:
A57: Standing Water:
A58: Thatch:
A59: Earthworm Rapid Assessment Rank:
A67: Drainage Class:
A75: Height of moss hummocks: | B75: _____ cm
A76: Depth of standing water: (>) | B76: _____ cm
A79: Exposed rock: | B79: ____ %
A80: Rock type:
A91: Additional Remarks:
A93: Life Form | D93: Height
A94: B | B94: Broadleaf evergreen | D94: >35m | E94: 8
A95: D | B95: Broadleaf deciduous | D95: 20-35m | E95: 7
A96: E | B96: Needleleaf evergreen | D96: 10-20m | E96: 6
A97: G | B97: Graminoids | D97: 5-10m | E97: 5
...

Sheet Vegetation Sheet
A1: DAKOTA COUNTY VEGETATION DATA SHEET
A2: Releve Name:
A3: Surveyor's Name:
A4: MN County: Dakota
A5: Date:
A6: GPS:
A7: Plant Community:
A9: ID | B9: Scientific Name | C9: Common Name | D9: CC | E9: CC Range | F9: Midpoint CC | G9: Physiognamy | H9: MN Nativity | I9: MNWI | J9: Rarity Status

Sheet Species List
A1: MN DNR Official Name | B1: Common Name | C1: C-value1 | D1: P | E1: MN Nativity | F1: MNWI | G1: RS | H1: Cover Class | I1: CC Range | J1: Midpoint CC | M1: Wc | N1: ID | O1: Native Plant Community
A2: Abies balsamea | B2: balsam fir | C2: 4 | D2: E | E2: Native | F2: FACW | H2: r | I2: >0-1% | J2: 0.5 | N2: cf. | O2: FDc25 Central Dry Oak-Aspen (Pine) Woodland
A3: Abutilon theophrasti | B3: velvet leaf | C3: 0 | D3: H | E3: Introduced | F3: FACU- | H3: + | I3: >1-5% | J3: 3 | O3: FDs27 Southern Dry-Mesic Pine-Oak Woodland
A4: Acalypha rhomboidea | B4: three-seeded mercury | C4: 0 | D4: H | E4: Native | F4: FACU | H4: 1 | I4: >1-5% | J4: 3 | O4: FDs37 Southern Dry-Mesic Oak (Maple) Woodland
A5: Acer ginnala | B5: amur maple | C5: 0 | D5: D | E5: Introduced | H5: 2 | I5: >5-25% | J5: 15 | O5: FDs38 Southern Dry-Mesic Oak-Hickory Woodland
A6: Acer negundo | B6: box elder | C6: 1 | D6: D | E6: Native | F6: FACW- | H6: 3 | I6: >25-50% | J6: 37.5 | O6: MHc26 Central Dry-Mesic Oak-Aspen Forest
A7: Acer negundo var. interius | B7: box elder | C7: 1 | D7: D | E7: Native | H7: 4 | I7: >50-75% | J7: 62.5 | O7: MHc36 Central Mesic Hardwood Forest (Eastern)
A8: Acer negundo var. negundo | B8: box elder | C8: 1 | D8: D | E8: Native | H8: 5 | I8: >75-100% | J8: 87.5 | O8: MHc38 Central Mesic Cold-Slope Hardwood-Conifer Forest
A9: Acer nigrum | B9: black maple | C9: 5 | D9: D | E9: Native | F9: FACU | O9: MHc47 Central Wet-Mesic Hardwood Forest
A10: Acer platanoides | B10: Norway maple | C10: 0 | D10: D | E10: Introduced | F10: UPL | O10: MHs37 Southern Dry-Mesic Oak Forest
A11: Acer rubrum | B11: red maple | C11: 3 | D11: D | E11: Native | F11: [FAC] | O11: MHs38 Southern Mesic Oak-Basswood Forest
A12: Acer saccharinum | B12: silver maple | C12: 3 | D12: D | E12: Native | F12: FACW | O12: MHs39 Southern Mesic Maple-Basswood Forest
A13: Acer saccharum | B13: sugar maple | C13: 5 | D13: D | E13: Native | F13: [FACU] | O13: MHs49 Southern Wet-Mesic Hardwood Forest
A14: Acer spicatum | B14: mountain maple | C14: 5 | D14: D | E14: Native | F14: FACU* | O14: FFs59 Southern Terrace Forest
A15: Acer spp. | O15: FFs68 Southern Floodplain Forest
A16: Achillea alpina | B16: Siberian yarrow | D16: H | G16: T | O16: WFn53 Northern Wet Cedar Forest
A17: Achillea millefolium | B17: common yarrow | C17: 1 | D17: H | E17: Native | F17: FACU | O17: WFn55 Northern Wet Ash Swamp
A18: Achillea ptarmica | B18: pearly yarrow | C18: 0 | D18: H | E18: Introduced | F18: FACU | O18: WFn64 Northern Very Wet Ash Swamp
A19: Achillea spp. | O19: WFs55 Southern Wet Aspen Forest
A20: Achnatherum hymenoides | B20: Indian rice grass | C20: 6 | D20: G | E20: Native | F20: [FACU+] | G20: E | O20: WFs57 Southern Wet Ash Swamp
A21: Acorus americanus | B21: sweet flag | C21: 7 | D21: H | E21: Native | F21: [OBL] | O21: FPs63 Southern Rich Conifer Swamp
A22: Actaea pachypoda | B22: white baneberry | C22: 6 | D22: H | E22: Native | F22: FACU | O22: APn81 Northern Poor Conifer Swamp
A23: Actaea rubra | B23: red baneberry | C23: 7 | D23: H | E23: Native | F23: FACU | O23: CTs12 Southern Dry Cliff
A24: Actaea sp. | B24: baneberry | C24: 6 | D24: H | E24: Native | F24: FACU | O24: CTs23 Southern Open Talus
A25: Adiantum pedatum | B25: maidenhair fern | C25: 7 | D25: H | E25: Native | F25: FAC- | O25: CTs33 Southern Mesic Cliff
A26: Adlumia fungosa | B26: Allegheny vine | C26: 7 | D26: H | E26: Native | G26: SC | O26: CTs43 Southern Maderate Cliff
A27: Adoxa moschatellina | B27: moschatel | C27: 9 | D27: H | E27: Native | F27: FAC | O27: CTs46 Southern Algific Talus
A28: Aegopodium podagraria | B28: goutweed | C28: 0 | D28: H | E28: Introduced | F28: FAC | O28: CTs53 Southern Wet Cliff
A29: Aethusa cynapium | B29: fool's-parsley | C29: 0 | D29: H | E29: Introduced | O29: ROs12 Southern Bedrock Outcrop
A30: Agalinis aspera | B30: rough false foxglove | C30: 7 | D30: H | E30: Native | F30: FAC- | O30: LKi32 Inland Lake Sand/Gravel/Cobble Shore
A31: Agalinis auriculata | B31: eared false foxglove | C31: 9 | D31: H | E31: Native | G31: E | O31: LKi43 Inland Lake Rocky Shore
A32: Agalinis gattingeri | B32: round-stemmed false foxglove | C32: 8 | D32: H | E32: Native | G32: E | O32: LKi54 Inland Lake Clay/Mud Shore
A33: Agalinis purpurea | B33: purple false foxglove | C33: 7 | D33: H | E33: Native | F33: FACW | O33: RVx32 Sand/Gravel/Cobble River Shore
A34: Agalinis purpurea var. parviflora | B34: purple false foxglove | C34: 7 | D34: H | E34: Native | F34: OBL | O34: RVx43 Rocky River Shore
A35: Agalinis purpurea var. purpurea | B35: purple false foxglove | D35: H | E35: Native | G35: W | O35: RVx54 Clay/Mud River Shore
A36: Agalinis sp. | B36: false foxglove | C36: 3 | D36: H | E36: Native | O36: UPs13 Southern Dry Prairie
A37: Agalinis tenuifolia | B37: slender-leaved false foxglove | C37: 3 | D37: H | E37: Native | F37: FACW | O37: UPs14 Southern Dry Savanna
A38: Agastache foeniculum | B38: blue giant hyssop | C38: 6 | D38: H | E38: Native | O38: UPs23 Southern Mesic Prairie
A39: Agastache nepetoides | B39: yellow giant hyssop | C39: 4 | D39: H | E39: Native | F39: FACU | G39: H | O39: UPs24 Southern Mesic Savanna
A40: Agastache scrophulariaefolia | B40: purple giant hyssop | C40: 4 | D40: H | E40: Native | O40: APn91 Northern Poor Fen
...

Sheet Woody
A1: DAKOTA COUNTY VEGETATION DATA SHEET
A2: Releve Name: | B2: WWRP WL Rel | C2: =CONCATENATE(B2,2024) -> WWRP WL Rel2024
A3: Surveyor's Name:
A4: MN County:
A5: Date:
A6: GPS:
A7: Plant Community:
A9: Scientific Name | B9: Common Name | C9: --> | D9: C Value | E9: Physiognamy | F9: MN Nativity | G9: MNWI | H9: Rarity Status | I9: ID | J9: CC | K9: CC Range | L9: --> | M9: Midpoint CC | N9: p | O9: pC
A10: Parthenocissus sp. | B10: =IF(LEN(VLOOKUP(A10,'Species List'!$A:$G,2,FALSE))=0,"",VLOOKUP(A10,'Species List'!$A:$G,2,FALSE)) | C10: =IF(LEN(VLOOKUP(A10,'Species List'!$A:$G,3,FALSE))=0,"",VLOOKUP(A10,'Species List'!$A:$G,3,FALSE)) -> 2 | D10: =VALUE(C10) -> 2 | E10: =IF(LEN(VLOOKUP(A10,'Species List'!$A:$G,4,FALSE))=0,"",VLOOKUP(A10,'Species List'!$A:$G,4,FALSE)) -> C | F10: =IF(LEN(VLOOKUP(A10,'Species List'!$A:$G,5,FALSE))=0,"",VLOOKUP(A10,'Species List'!$A:$G,5,FALSE)) -> Native | G10: =IF(LEN(VLOOKUP(A10,'Species List'!$A:$G,6,FALSE))=0,"",VLOOKUP(A10,'Species List'!$A:$G,6,FALSE)) | H10: =VLOOKUP(A10,'Species List'!$A:$G,7,FALSE) -> 0 | J10: + | K10: =VLOOKUP(J10,'Species List'!$H$1:$J$9,2,FALSE) -> >1-5% | L10: =VLOOKUP(K10,'Species List'!$I$1:$N$8,2,FALSE) -> 3 | M10: =VALUE(L10) -> 3 | N10: =L10/$L$151 -> 0.020134228 | O10: =D10*N10 -> 0.040268456
A11: Prunus serotina | B11: =IF(LEN(VLOOKUP(A11,'Species List'!$A:$G,2,FALSE))=0,"",VLOOKUP(A11,'Species List'!$A:$G,2,FALSE)) -> black cherry | C11: =IF(LEN(VLOOKUP(A11,'Species List'!$A:$G,3,FALSE))=0,"",VLOOKUP(A11,'Species List'!$A:$G,3,FALSE)) -> 4 | D11: =VALUE(C11) -> 4 | E11: =IF(LEN(VLOOKUP(A11,'Species List'!$A:$G,4,FALSE))=0,"",VLOOKUP(A11,'Species List'!$A:$G,4,FALSE)) -> D | F11: =IF(LEN(VLOOKUP(A11,'Species List'!$A:$G,5,FALSE))=0,"",VLOOKUP(A11,'Species List'!$A:$G,5,FALSE)) -> Native | G11: =IF(LEN(VLOOKUP(A11,'Species List'!$A:$G,6,FALSE))=0,"",VLOOKUP(A11,'Species List'!$A:$G,6,FALSE)) -> [FACU] | H11: =VLOOKUP(A11,'Species List'!$A:$G,7,FALSE) -> 0 | J11: r | K11: =VLOOKUP(J11,'Species List'!$H$1:$J$9,2,FALSE) -> >0-1% | L11: =VLOOKUP(K11,'Species List'!$I$1:$N$8,2,FALSE) -> 0.5 | M11: =VALUE(L11) -> 0.5 | N11: =L11/$L$151 -> 0.0033557047 | O11: =D11*N11 -> 0.013422819
A12: Prunus virginiana | B12: =IF(LEN(VLOOKUP(A12,'Species List'!$A:$G,2,FALSE))=0,"",VLOOKUP(A12,'Species List'!$A:$G,2,FALSE)) -> chokecherry | C12: =IF(LEN(VLOOKUP(A12,'Species List'!$A:$G,3,FALSE))=0,"",VLOOKUP(A12,'Species List'!$A:$G,3,FALSE)) -> 3 | D12: =VALUE(C12) -> 3 | E12: =IF(LEN(VLOOKUP(A12,'Species List'!$A:$G,4,FALSE))=0,"",VLOOKUP(A12,'Species List'!$A:$G,4,FALSE)) -> D | F12: =IF(LEN(VLOOKUP(A12,'Species List'!$A:$G,5,FALSE))=0,"",VLOOKUP(A12,'Species List'!$A:$G,5,FALSE)) -> Native | G12: =IF(LEN(VLOOKUP(A12,'Species List'!$A:$G,6,FALSE))=0,"",VLOOKUP(A12,'Species List'!$A:$G,6,FALSE)) -> [FAC-] | H12: =VLOOKUP(A12,'Species List'!$A:$G,7,FALSE) -> 0 | J12: 2 | K12: =VLOOKUP(J12,'Species List'!$H$1:$J$9,2,FALSE) -> >5-25% | L12: =VLOOKUP(K12,'Species List'!$I$1:$N$8,2,FALSE) -> 15 | M12: =VALUE(L12) -> 15 | N12: =L12/$L$151 -> 0.10067114 | O12: =D12*N12 -> 0.30201342
A13: Rubus occidentalis | B13: =IF(LEN(VLOOKUP(A13,'Species List'!$A:$G,2,FALSE))=0,"",VLOOKUP(A13,'Species List'!$A:$G,2,FALSE)) -> black raspberry | C13: =IF(LEN(VLOOKUP(A13,'Species List'!$A:$G,3,FALSE))=0,"",VLOOKUP(A13,'Species List'!$A:$G,3,FALSE)) -> 2 | D13: =VALUE(C13) -> 2 | E13: =IF(LEN(VLOOKUP(A13,'Species List'!$A:$G,4,FALSE))=0,"",VLOOKUP(A13,'Species List'!$A:$G,4,FALSE)) -> D | F13: =IF(LEN(VLOOKUP(A13,'Species List'!$A:$G,5,FALSE))=0,"",VLOOKUP(A13,'Species List'!$A:$G,5,FALSE)) -> Native | G13: =IF(LEN(VLOOKUP(A13,'Species List'!$A:$G,6,FALSE))=0,"",VLOOKUP(A13,'Species List'!$A:$G,6,FALSE)) | H13: =VLOOKUP(A13,'Species List'!$A:$G,7,FALSE) -> 0 | J13: 1 | K13: =VLOOKUP(J13,'Species List'!$H$1:$J$9,2,FALSE) -> >1-5% | L13: =VLOOKUP(K13,'Species List'!$I$1:$N$8,2,FALSE) -> 3 | M13: =VALUE(L13) -> 3 | N13: =L13/$L$151 -> 0.020134228 | O13: =D13*N13 -> 0.040268456
A14: Ribes sp. | B14: =IF(LEN(VLOOKUP(A14,'Species List'!$A:$G,2,FALSE))=0,"",VLOOKUP(A14,'Species List'!$A:$G,2,FALSE)) | C14: =IF(LEN(VLOOKUP(A14,'Species List'!$A:$G,3,FALSE))=0,"",VLOOKUP(A14,'Species List'!$A:$G,3,FALSE)) -> 3 | D14: =VALUE(C14) -> 3 | E14: =IF(LEN(VLOOKUP(A14,'Species List'!$A:$G,4,FALSE))=0,"",VLOOKUP(A14,'Species List'!$A:$G,4,FALSE)) -> D | F14: =IF(LEN(VLOOKUP(A14,'Species List'!$A:$G,5,FALSE))=0,"",VLOOKUP(A14,'Species List'!$A:$G,5,FALSE)) -> Native | G14: =IF(LEN(VLOOKUP(A14,'Species List'!$A:$G,6,FALSE))=0,"",VLOOKUP(A14,'Species List'!$A:$G,6,FALSE)) | H14: =VLOOKUP(A14,'Species List'!$A:$G,7,FALSE) -> 0 | J14: + | K14: =VLOOKUP(J14,'Species List'!$H$1:$J$9,2,FALSE) -> >1-5% | L14: =VLOOKUP(K14,'Species List'!$I$1:$N$8,2,FALSE) -> 3 | M14: =VALUE(L14) -> 3 | N14: =L14/$L$151 -> 0.020134228 | O14: =D14*N14 -> 0.060402685
A15: Celtis occidentalis | B15: =IF(LEN(VLOOKUP(A15,'Species List'!$A:$G,2,FALSE))=0,"",VLOOKUP(A15,'Species List'!$A:$G,2,FALSE)) -> hackberry | C15: =IF(LEN(VLOOKUP(A15,'Species List'!$A:$G,3,FALSE))=0,"",VLOOKUP(A15,'Species List'!$A:$G,3,FALSE)) -> 3 | D15: =VALUE(C15) -> 3 | E15: =IF(LEN(VLOOKUP(A15,'Species List'!$A:$G,4,FALSE))=0,"",VLOOKUP(A15,'Species List'!$A:$G,4,FALSE)) -> D | F15: =IF(LEN(VLOOKUP(A15,'Species List'!$A:$G,5,FALSE))=0,"",VLOOKUP(A15,'Species List'!$A:$G,5,FALSE)) -> Native | G15: =IF(LEN(VLOOKUP(A15,'Species List'!$A:$G,6,FALSE))=0,"",VLOOKUP(A15,'Species List'!$A:$G,6,FALSE)) -> [FAC-] | H15: =VLOOKUP(A15,'Species List'!$A:$G,7,FALSE) -> 0 | J15: 2 | K15: =VLOOKUP(J15,'Species List'!$H$1:$J$9,2,FALSE) -> >5-25% | L15: =VLOOKUP(K15,'Species List'!$I$1:$N$8,2,FALSE) -> 15 | M15: =VALUE(L15) -> 15 | N15: =L15/$L$151 -> 0.10067114 | O15: =D15*N15 -> 0.30201342
A16: Populus grandidentata | B16: =IF(LEN(VLOOKUP(A16,'Species List'!$A:$G,2,FALSE))=0,"",VLOOKUP(A16,'Species List'!$A:$G,2,FALSE)) -> big-toothed aspen | C16: =IF(LEN(VLOOKUP(A16,'Species List'!$A:$G,3,FALSE))=0,"",VLOOKUP(A16,'Species List'!$A:$G,3,FALSE)) -> 4 | D16: =VALUE(C16) -> 4 | E16: =IF(LEN(VLOOKUP(A16,'Species List'!$A:$G,4,FALSE))=0,"",VLOOKUP(A16,'Species List'!$A:$G,4,FALSE)) -> D | F16: =IF(LEN(VLOOKUP(A16,'Species List'!$A:$G,5,FALSE))=0,"",VLOOKUP(A16,'Species List'!$A:$G,5,FALSE)) -> Native | G16: =IF(LEN(VLOOKUP(A16,'Species List'!$A:$G,6,FALSE))=0,"",VLOOKUP(A16,'Species List'!$A:$G,6,FALSE)) -> FACU | H16: =VLOOKUP(A16,'Species List'!$A:$G,7,FALSE) -> 0 | J16: + | K16: =VLOOKUP(J16,'Species List'!$H$1:$J$9,2,FALSE) -> >1-5% | L16: =VLOOKUP(K16,'Species List'!$I$1:$N$8,2,FALSE) -> 3 | M16: =VALUE(L16) -> 3 | N16: =L16/$L$151 -> 0.020134228 | O16: =D16*N16 -> 0.080536913
A17: Ulmus americana | B17: =IF(LEN(VLOOKUP(A17,'Species List'!$A:$G,2,FALSE))=0,"",VLOOKUP(A17,'Species List'!$A:$G,2,FALSE)) -> American elm | C17: =IF(LEN(VLOOKUP(A17,'Species List'!$A:$G,3,FALSE))=0,"",VLOOKUP(A17,'Species List'!$A:$G,3,FALSE)) -> 3 | D17: =VALUE(C17) -> 3 | E17: =IF(LEN(VLOOKUP(A17,'Species List'!$A:$G,4,FALSE))=0,"",VLOOKUP(A17,'Species List'!$A:$G,4,FALSE)) -> D | F17: =IF(LEN(VLOOKUP(A17,'Species List'!$A:$G,5,FALSE))=0,"",VLOOKUP(A17,'Species List'!$A:$G,5,FALSE)) -> Native | G17: =IF(LEN(VLOOKUP(A17,'Species List'!$A:$G,6,FALSE))=0,"",VLOOKUP(A17,'Species List'!$A:$G,6,FALSE)) -> FACW- | H17: =VLOOKUP(A17,'Species List'!$A:$G,7,FALSE) -> 0 | J17: + | K17: =VLOOKUP(J17,'Species List'!$H$1:$J$9,2,FALSE) -> >1-5% | L17: =VLOOKUP(K17,'Species List'!$I$1:$N$8,2,FALSE) -> 3 | M17: =VALUE(L17) -> 3 | N17: =L17/$L$151 -> 0.020134228 | O17: =D17*N17 -> 0.060402685
A18: Sambucus sp. | B18: =IF(LEN(VLOOKUP(A18,'Species List'!$A:$G,2,FALSE))=0,"",VLOOKUP(A18,'Species List'!$A:$G,2,FALSE)) | C18: =IF(LEN(VLOOKUP(A18,'Species List'!$A:$G,3,FALSE))=0,"",VLOOKUP(A18,'Species List'!$A:$G,3,FALSE)) -> 3 | D18: =VALUE(C18) -> 3 | E18: =IF(LEN(VLOOKUP(A18,'Species List'!$A:$G,4,FALSE))=0,"",VLOOKUP(A18,'Species List'!$A:$G,4,FALSE)) -> D | F18: =IF(LEN(VLOOKUP(A18,'Species List'!$A:$G,5,FALSE))=0,"",VLOOKUP(A18,'Species List'!$A:$G,5,FALSE)) -> Native | G18: =IF(LEN(VLOOKUP(A18,'Species List'!$A:$G,6,FALSE))=0,"",VLOOKUP(A18,'Species List'!$A:$G,6,FALSE)) | H18: =VLOOKUP(A18,'Species List'!$A:$G,7,FALSE) -> 0 | J18: r | K18: =VLOOKUP(J18,'Species List'!$H$1:$J$9,2,FALSE) -> >0-1% | L18: =VLOOKUP(K18,'Species List'!$I$1:$N$8,2,FALSE) -> 0.5 | M18: =VALUE(L18) -> 0.5 | N18: =L18/$L$151 -> 0.0033557047 | O18: =D18*N18 -> 0.010067114
A20: Exotic honeysuckle spp. | B20: =IF(LEN(VLOOKUP(A20,'Species List'!$A:$G,2,FALSE))=0,"",VLOOKUP(A20,'Species List'!$A:$G,2,FALSE)) | C20: =IF(LEN(VLOOKUP(A20,'Species List'!$A:$G,3,FALSE))=0,"",VLOOKUP(A20,'Species List'!$A:$G,3,FALSE)) -> 0 | D20: =VALUE(C20) -> 0 | E20: =IF(LEN(VLOOKUP(A20,'Species List'!$A:$G,4,FALSE))=0,"",VLOOKUP(A20,'Species List'!$A:$G,4,FALSE)) -> D | F20: =IF(LEN(VLOOKUP(A20,'Species List'!$A:$G,5,FALSE))=0,"",VLOOKUP(A20,'Species List'!$A:$G,5,FALSE)) -> Introduced | G20: =IF(LEN(VLOOKUP(A20,'Species List'!$A:$G,6,FALSE))=0,"",VLOOKUP(A20,'Species List'!$A:$G,6,FALSE)) | H20: =VLOOKUP(A20,'Species List'!$A:$G,7,FALSE) -> 0 | J20: r | K20: =VLOOKUP(J20,'Species List'!$H$1:$J$9,2,FALSE) -> >0-1% | L20: =VLOOKUP(K20,'Species List'!$I$1:$N$8,2,FALSE) -> 0.5 | M20: =VALUE(L20) -> 0.5 | N20: =L20/$L$151 -> 0.0033557047 | O20: =D20*N20 -> 0
A22: Acer negundo | B22: =IF(LEN(VLOOKUP(A22,'Species List'!$A:$G,2,FALSE))=0,"",VLOOKUP(A22,'Species List'!$A:$G,2,FALSE)) -> box elder | C22: =IF(LEN(VLOOKUP(A22,'Species List'!$A:$G,3,FALSE))=0,"",VLOOKUP(A22,'Species List'!$A:$G,3,FALSE)) -> 1 | D22: =VALUE(C22) -> 1 | E22: =IF(LEN(VLOOKUP(A22,'Species List'!$A:$G,4,FALSE))=0,"",VLOOKUP(A22,'Species List'!$A:$G,4,FALSE)) -> D | F22: =IF(LEN(VLOOKUP(A22,'Species List'!$A:$G,5,FALSE))=0,"",VLOOKUP(A22,'Species List'!$A:$G,5,FALSE)) -> Native | G22: =IF(LEN(VLOOKUP(A22,'Species List'!$A:$G,6,FALSE))=0,"",VLOOKUP(A22,'Species List'!$A:$G,6,FALSE)) -> FACW- | H22: =VLOOKUP(A22,'Species List'!$A:$G,7,FALSE) -> 0 | J22: 2 | K22: =VLOOKUP(J22,'Species List'!$H$1:$J$9,2,FALSE) -> >5-25% | L22: =VLOOKUP(K22,'Species List'!$I$1:$N$8,2,FALSE) -> 15 | M22: =VALUE(L22) -> 15 | N22: =L22/$L$151 -> 0.10067114 | O22: =D22*N22 -> 0.10067114
A23: Quercus macrocarpa | B23: =IF(LEN(VLOOKUP(A23,'Species List'!$A:$G,2,FALSE))=0,"",VLOOKUP(A23,'Species List'!$A:$G,2,FALSE)) -> bur oak | C23: =IF(LEN(VLOOKUP(A23,'Species List'!$A:$G,3,FALSE))=0,"",VLOOKUP(A23,'Species List'!$A:$G,3,FALSE)) -> 5 | D23: =VALUE(C23) -> 5 | E23: =IF(LEN(VLOOKUP(A23,'Species List'!$A:$G,4,FALSE))=0,"",VLOOKUP(A23,'Species List'!$A:$G,4,FALSE)) -> D | F23: =IF(LEN(VLOOKUP(A23,'Species List'!$A:$G,5,FALSE))=0,"",VLOOKUP(A23,'Species List'!$A:$G,5,FALSE)) -> Native | G23: =IF(LEN(VLOOKUP(A23,'Species List'!$A:$G,6,FALSE))=0,"",VLOOKUP(A23,'Species List'!$A:$G,6,FALSE)) -> [FAC-] | H23: =VLOOKUP(A23,'Species List'!$A:$G,7,FALSE) -> 0 | J23: 5 | K23: =VLOOKUP(J23,'Species List'!$H$1:$J$9,2,FALSE) -> >75-100% | L23: =VLOOKUP(K23,'Species List'!$I$1:$N$8,2,FALSE) -> 87.5 | M23: =VALUE(L23) -> 87.5 | N23: =L23/$L$151 -> 0.58724832 | O23: =D23*N23 -> 2.9362416
B24: =IF(LEN(VLOOKUP(A24,'Species List'!$A:$G,2,FALSE))=0,"",VLOOKUP(A24,'Species List'!$A:$G,2,FALSE)) -> #N/A | C24: =IF(LEN(VLOOKUP(A24,'Species List'!$A:$G,3,FALSE))=0,"",VLOOKUP(A24,'Species List'!$A:$G,3,FALSE)) -> #N/A | D24: =VALUE(C24) -> #N/A | E24: =IF(LEN(VLOOKUP(A24,'Species List'!$A:$G,4,FALSE))=0,"",VLOOKUP(A24,'Species List'!$A:$G,4,FALSE)) -> #N/A | F24: =IF(LEN(VLOOKUP(A24,'Species List'!$A:$G,5,FALSE))=0,"",VLOOKUP(A24,'Species List'!$A:$G,5,FALSE)) -> #N/A | G24: =IF(LEN(VLOOKUP(A24,'Species List'!$A:$G,6,FALSE))=0,"",VLOOKUP(A24,'Species List'!$A:$G,6,FALSE)) -> #N/A | H24: =VLOOKUP(A24,'Species List'!$A:$G,7,FALSE) -> #N/A | K24: =VLOOKUP(J24,'Species List'!$H$1:$J$9,2,FALSE) -> #N/A | L24: =VLOOKUP(K24,'Species List'!$I$1:$N$8,2,FALSE) -> #N/A | M24: =VALUE(L24) -> #N/A | N24: =L24/$L$151 -> #N/A | O24: =D24*N24 -> #N/A
B25: =IF(LEN(VLOOKUP(A25,'Species List'!$A:$G,2,FALSE))=0,"",VLOOKUP(A25,'Species List'!$A:$G,2,FALSE)) -> #N/A | C25: =IF(LEN(VLOOKUP(A25,'Species List'!$A:$G,3,FALSE))=0,"",VLOOKUP(A25,'Species List'!$A:$G,3,FALSE)) -> #N/A | D25: =VALUE(C25) -> #N/A | E25: =IF(LEN(VLOOKUP(A25,'Species List'!$A:$G,4,FALSE))=0,"",VLOOKUP(A25,'Species List'!$A:$G,4,FALSE)) -> #N/A | F25: =IF(LEN(VLOOKUP(A25,'Species List'!$A:$G,5,FALSE))=0,"",VLOOKUP(A25,'Species List'!$A:$G,5,FALSE)) -> #N/A | G25: =IF(LEN(VLOOKUP(A25,'Species List'!$A:$G,6,FALSE))=0,"",VLOOKUP(A25,'Species List'!$A:$G,6,FALSE)) -> #N/A | H25: =VLOOKUP(A25,'Species List'!$A:$G,7,FALSE) -> #N/A | K25: =VLOOKUP(J25,'Species List'!$H$1:$J$9,2,FALSE) -> #N/A | L25: =VLOOKUP(K25,'Species List'!$I$1:$N$8,2,FALSE) -> #N/A | M25: =VALUE(L25) -> #N/A | N25: =L25/$L$151 -> #N/A | O25: =D25*N25 -> #N/A
B26: =IF(LEN(VLOOKUP(A26,'Species List'!$A:$G,2,FALSE))=0,"",VLOOKUP(A26,'Species List'!$A:$G,2,FALSE)) -> #N/A | C26: =IF(LEN(VLOOKUP(A26,'Species List'!$A:$G,3,FALSE))=0,"",VLOOKUP(A26,'Species List'!$A:$G,3,FALSE)) -> #N/A | D26: =VALUE(C26) -> #N/A | E26: =IF(LEN(VLOOKUP(A26,'Species List'!$A:$G,4,FALSE))=0,"",VLOOKUP(A26,'Species List'!$A:$G,4,FALSE)) -> #N/A | F26: =IF(LEN(VLOOKUP(A26,'Species List'!$A:$G,5,FALSE))=0,"",VLOOKUP(A26,'Species List'!$A:$G,5,FALSE)) -> #N/A | G26: =IF(LEN(VLOOKUP(A26,'Species List'!$A:$G,6,FALSE))=0,"",VLOOKUP(A26,'Species List'!$A:$G,6,FALSE)) -> #N/A | H26: =VLOOKUP(A26,'Species List'!$A:$G,7,FALSE) -> #N/A | K26: =VLOOKUP(J26,'Species List'!$H$1:$J$9,2,FALSE) -> #N/A | L26: =VLOOKUP(K26,'Species List'!$I$1:$N$8,2,FALSE) -> #N/A | M26: =VALUE(L26) -> #N/A | N26: =L26/$L$151 -> #N/A | O26: =D26*N26 -> #N/A
B27: =IF(LEN(VLOOKUP(A27,'Species List'!$A:$G,2,FALSE))=0,"",VLOOKUP(A27,'Species List'!$A:$G,2,FALSE)) -> #N/A | C27: =IF(LEN(VLOOKUP(A27,'Species List'!$A:$G,3,FALSE))=0,"",VLOOKUP(A27,'Species List'!$A:$G,3,FALSE)) -> #N/A | D27: =VALUE(C27) -> #N/A | E27: =IF(LEN(VLOOKUP(A27,'Species List'!$A:$G,4,FALSE))=0,"",VLOOKUP(A27,'Species List'!$A:$G,4,FALSE)) -> #N/A | F27: =IF(LEN(VLOOKUP(A27,'Species List'!$A:$G,5,FALSE))=0,"",VLOOKUP(A27,'Species List'!$A:$G,5,FALSE)) -> #N/A | G27: =IF(LEN(VLOOKUP(A27,'Species List'!$A:$G,6,FALSE))=0,"",VLOOKUP(A27,'Species List'!$A:$G,6,FALSE)) -> #N/A | H27: =VLOOKUP(A27,'Species List'!$A:$G,7,FALSE) -> #N/A | K27: =VLOOKUP(J27,'Species List'!$H$1:$J$9,2,FALSE) -> #N/A | L27: =VLOOKUP(K27,'Species List'!$I$1:$N$8,2,FALSE) -> #N/A | M27: =VALUE(L27) -> #N/A | N27: =L27/$L$151 -> #N/A | O27: =D27*N27 -> #N/A
B28: =IF(LEN(VLOOKUP(A28,'Species List'!$A:$G,2,FALSE))=0,"",VLOOKUP(A28,'Species List'!$A:$G,2,FALSE)) -> #N/A | C28: =IF(LEN(VLOOKUP(A28,'Species List'!$A:$G,3,FALSE))=0,"",VLOOKUP(A28,'Species List'!$A:$G,3,FALSE)) -> #N/A | D28: =VALUE(C28) -> #N/A | E28: =IF(LEN(VLOOKUP(A28,'Species List'!$A:$G,4,FALSE))=0,"",VLOOKUP(A28,'Species List'!$A:$G,4,FALSE)) -> #N/A | F28: =IF(LEN(VLOOKUP(A28,'Species List'!$A:$G,5,FALSE))=0,"",VLOOKUP(A28,'Species List'!$A:$G,5,FALSE)) -> #N/A | G28: =IF(LEN(VLOOKUP(A28,'Species List'!$A:$G,6,FALSE))=0,"",VLOOKUP(A28,'Species List'!$A:$G,6,FALSE)) -> #N/A | H28: =VLOOKUP(A28,'Species List'!$A:$G,7,FALSE) -> #N/A | K28: =VLOOKUP(J28,'Species List'!$H$1:$J$9,2,FALSE) -> #N/A | L28: =VLOOKUP(K28,'Species List'!$I$1:$N$8,2,FALSE) -> #N/A | M28: =VALUE(L28) -> #N/A | N28: =L28/$L$151 -> #N/A | O28: =D28*N28 -> #N/A
B29: =IF(LEN(VLOOKUP(A29,'Species List'!$A:$G,2,FALSE))=0,"",VLOOKUP(A29,'Species List'!$A:$G,2,FALSE)) -> #N/A | C29: =IF(LEN(VLOOKUP(A29,'Species List'!$A:$G,3,FALSE))=0,"",VLOOKUP(A29,'Species List'!$A:$G,3,FALSE)) -> #N/A | D29: =VALUE(C29) -> #N/A | E29: =IF(LEN(VLOOKUP(A29,'Species List'!$A:$G,4,FALSE))=0,"",VLOOKUP(A29,'Species List'!$A:$G,4,FALSE)) -> #N/A | F29: =IF(LEN(VLOOKUP(A29,'Species List'!$A:$G,5,FALSE))=0,"",VLOOKUP(A29,'Species List'!$A:$G,5,FALSE)) -> #N/A | G29: =IF(LEN(VLOOKUP(A29,'Species List'!$A:$G,6,FALSE))=0,"",VLOOKUP(A29,'Species List'!$A:$G,6,FALSE)) -> #N/A | H29: =VLOOKUP(A29,'Species List'!$A:$G,7,FALSE) -> #N/A | K29: =VLOOKUP(J29,'Species List'!$H$1:$J$9,2,FALSE) -> #N/A | L29: =VLOOKUP(K29,'Species List'!$I$1:$N$8,2,FALSE) -> #N/A | M29: =VALUE(L29) -> #N/A | N29: =L29/$L$151 -> #N/A | O29: =D29*N29 -> #N/A
B30: =IF(LEN(VLOOKUP(A30,'Species List'!$A:$G,2,FALSE))=0,"",VLOOKUP(A30,'Species List'!$A:$G,2,FALSE)) -> #N/A | C30: =IF(LEN(VLOOKUP(A30,'Species List'!$A:$G,3,FALSE))=0,"",VLOOKUP(A30,'Species List'!$A:$G,3,FALSE)) -> #N/A | D30: =VALUE(C30) -> #N/A | E30: =IF(LEN(VLOOKUP(A30,'Species List'!$A:$G,4,FALSE))=0,"",VLOOKUP(A30,'Species List'!$A:$G,4,FALSE)) -> #N/A | F30: =IF(LEN(VLOOKUP(A30,'Species List'!$A:$G,5,FALSE))=0,"",VLOOKUP(A30,'Species List'!$A:$G,5,FALSE)) -> #N/A | G30: =IF(LEN(VLOOKUP(A30,'Species List'!$A:$G,6,FALSE))=0,"",VLOOKUP(A30,'Species List'!$A:$G,6,FALSE)) -> #N/A | H30: =VLOOKUP(A30,'Species List'!$A:$G,7,FALSE) -> #N/A | K30: =VLOOKUP(J30,'Species List'!$H$1:$J$9,2,FALSE) -> #N/A | L30: =VLOOKUP(K30,'Species List'!$I$1:$N$8,2,FALSE) -> #N/A | M30: =VALUE(L30) -> #N/A | N30: =L30/$L$151 -> #N/A | O30: =D30*N30 -> #N/A
B31: =IF(LEN(VLOOKUP(A31,'Species List'!$A:$G,2,FALSE))=0,"",VLOOKUP(A31,'Species List'!$A:$G,2,FALSE)) -> #N/A | C31: =IF(LEN(VLOOKUP(A31,'Species List'!$A:$G,3,FALSE))=0,"",VLOOKUP(A31,'Species List'!$A:$G,3,FALSE)) -> #N/A | D31: =VALUE(C31) -> #N/A | E31: =IF(LEN(VLOOKUP(A31,'Species List'!$A:$G,4,FALSE))=0,"",VLOOKUP(A31,'Species List'!$A:$G,4,FALSE)) -> #N/A | F31: =IF(LEN(VLOOKUP(A31,'Species List'!$A:$G,5,FALSE))=0,"",VLOOKUP(A31,'Species List'!$A:$G,5,FALSE)) -> #N/A | G31: =IF(LEN(VLOOKUP(A31,'Species List'!$A:$G,6,FALSE))=0,"",VLOOKUP(A31,'Species List'!$A:$G,6,FALSE)) -> #N/A | H31: =VLOOKUP(A31,'Species List'!$A:$G,7,FALSE) -> #N/A | K31: =VLOOKUP(J31,'Species List'!$H$1:$J$9,2,FALSE) -> #N/A | L31: =VLOOKUP(K31,'Species List'!$I$1:$N$8,2,FALSE) -> #N/A | M31: =VALUE(L31) -> #N/A | N31: =L31/$L$151 -> #N/A | O31: =D31*N31 -> #N/A
B32: =IF(LEN(VLOOKUP(A32,'Species List'!$A:$G,2,FALSE))=0,"",VLOOKUP(A32,'Species List'!$A:$G,2,FALSE)) -> #N/A | C32: =IF(LEN(VLOOKUP(A32,'Species List'!$A:$G,3,FALSE))=0,"",VLOOKUP(A32,'Species List'!$A:$G,3,FALSE)) -> #N/A | D32: =VALUE(C32) -> #N/A | E32: =IF(LEN(VLOOKUP(A32,'Species List'!$A:$G,4,FALSE))=0,"",VLOOKUP(A32,'Species List'!$A:$G,4,FALSE)) -> #N/A | F32: =IF(LEN(VLOOKUP(A32,'Species List'!$A:$G,5,FALSE))=0,"",VLOOKUP(A32,'Species List'!$A:$G,5,FALSE)) -> #N/A | G32: =IF(LEN(VLOOKUP(A32,'Species List'!$A:$G,6,FALSE))=0,"",VLOOKUP(A32,'Species List'!$A:$G,6,FALSE)) -> #N/A | H32: =VLOOKUP(A32,'Species List'!$A:$G,7,FALSE) -> #N/A | K32: =VLOOKUP(J32,'Species List'!$H$1:$J$9,2,FALSE) -> #N/A | L32: =VLOOKUP(K32,'Species List'!$I$1:$N$8,2,FALSE) -> #N/A | M32: =VALUE(L32) -> #N/A | N32: =L32/$L$151 -> #N/A | O32: =D32*N32 -> #N/A
B33: =IF(LEN(VLOOKUP(A33,'Species List'!$A:$G,2,FALSE))=0,"",VLOOKUP(A33,'Species List'!$A:$G,2,FALSE)) -> #N/A | C33: =IF(LEN(VLOOKUP(A33,'Species List'!$A:$G,3,FALSE))=0,"",VLOOKUP(A33,'Species List'!$A:$G,3,FALSE)) -> #N/A | D33: =VALUE(C33) -> #N/A | E33: =IF(LEN(VLOOKUP(A33,'Species List'!$A:$G,4,FALSE))=0,"",VLOOKUP(A33,'Species List'!$A:$G,4,FALSE)) -> #N/A | F33: =IF(LEN(VLOOKUP(A33,'Species List'!$A:$G,5,FALSE))=0,"",VLOOKUP(A33,'Species List'!$A:$G,5,FALSE)) -> #N/A | G33: =IF(LEN(VLOOKUP(A33,'Species List'!$A:$G,6,FALSE))=0,"",VLOOKUP(A33,'Species List'!$A:$G,6,FALSE)) -> #N/A | H33: =VLOOKUP(A33,'Species List'!$A:$G,7,FALSE) -> #N/A | K33: =VLOOKUP(J33,'Species List'!$H$1:$J$9,2,FALSE) -> #N/A | L33: =VLOOKUP(K33,'Species List'!$I$1:$N$8,2,FALSE) -> #N/A | M33: =VALUE(L33) -> #N/A | N33: =L33/$L$151 -> #N/A | O33: =D33*N33 -> #N/A
B34: =IF(LEN(VLOOKUP(A34,'Species List'!$A:$G,2,FALSE))=0,"",VLOOKUP(A34,'Species List'!$A:$G,2,FALSE)) -> #N/A | C34: =IF(LEN(VLOOKUP(A34,'Species List'!$A:$G,3,FALSE))=0,"",VLOOKUP(A34,'Species List'!$A:$G,3,FALSE)) -> #N/A | D34: =VALUE(C34) -> #N/A | E34: =IF(LEN(VLOOKUP(A34,'Species List'!$A:$G,4,FALSE))=0,"",VLOOKUP(A34,'Species List'!$A:$G,4,FALSE)) -> #N/A | F34: =IF(LEN(VLOOKUP(A34,'Species List'!$A:$G,5,FALSE))=0,"",VLOOKUP(A34,'Species List'!$A:$G,5,FALSE)) -> #N/A | G34: =IF(LEN(VLOOKUP(A34,'Species List'!$A:$G,6,FALSE))=0,"",VLOOKUP(A34,'Species List'!$A:$G,6,FALSE)) -> #N/A | H34: =VLOOKUP(A34,'Species List'!$A:$G,7,FALSE) -> #N/A | K34: =VLOOKUP(J34,'Species List'!$H$1:$J$9,2,FALSE) -> #N/A | L34: =VLOOKUP(K34,'Species List'!$I$1:$N$8,2,FALSE) -> #N/A | M34: =VALUE(L34) -> #N/A | N34: =L34/$L$151 -> #N/A | O34: =D34*N34 -> #N/A
B35: =IF(LEN(VLOOKUP(A35,'Species List'!$A:$G,2,FALSE))=0,"",VLOOKUP(A35,'Species List'!$A:$G,2,FALSE)) -> #N/A | C35: =IF(LEN(VLOOKUP(A35,'Species List'!$A:$G,3,FALSE))=0,"",VLOOKUP(A35,'Species List'!$A:$G,3,FALSE)) -> #N/A | D35: =VALUE(C35) -> #N/A | E35: =IF(LEN(VLOOKUP(A35,'Species List'!$A:$G,4,FALSE))=0,"",VLOOKUP(A35,'Species List'!$A:$G,4,FALSE)) -> #N/A | F35: =IF(LEN(VLOOKUP(A35,'Species List'!$A:$G,5,FALSE))=0,"",VLOOKUP(A35,'Species List'!$A:$G,5,FALSE)) -> #N/A | G35: =IF(LEN(VLOOKUP(A35,'Species List'!$A:$G,6,FALSE))=0,"",VLOOKUP(A35,'Species List'!$A:$G,6,FALSE)) -> #N/A | H35: =VLOOKUP(A35,'Species List'!$A:$G,7,FALSE) -> #N/A | K35: =VLOOKUP(J35,'Species List'!$H$1:$J$9,2,FALSE) -> #N/A | L35: =VLOOKUP(K35,'Species List'!$I$1:$N$8,2,FALSE) -> #N/A | M35: =VALUE(L35) -> #N/A | N35: =L35/$L$151 -> #N/A | O35: =D35*N35 -> #N/A
... B150: =IF(LEN(VLOOKUP(A150,'Species List'!$A:$G,2,FALSE))=0,"",VLOOKUP(A150,'Species List'!$A:$G,2,FALSE)) -> #N/A | C150: =IF(LEN(VLOOKUP(A150,'Species List'!$A:$G,3,FALSE))=0,"",VLOOKUP(A150,'Species List'!$A:$G,3,FALSE)) -> #N/A | D150: =VALUE(C150) -> #N/A | E150: =IF(LEN(VLOOKUP(A150,'Species List'!$A:$G,4,FALSE))=0,"",VLOOKUP(A150,'Species List'!$A:$G,4,FALSE)) -> #N/A | F150: =IF(LEN(VLOOKUP(A150,'Species List'!$A:$G,5,FALSE))=0,"",VLOOKUP(A150,'Species List'!$A:$G,5,FALSE)) -> #N/A | G150: =IF(LEN(VLOOKUP(A150,'Species List'!$A:$G,6,FALSE))=0,"",VLOOKUP(A150,'Species List'!$A:$G,6,FALSE)) -> #N/A | H150: =VLOOKUP(A150,'Species List'!$A:$G,7,FALSE) -> #N/A | K150: =VLOOKUP(J150,'Species List'!$H$1:$J$9,2,FALSE) -> #N/A | L150: =VLOOKUP(K150,'Species List'!$I$1:$N$8,2,FALSE) -> #N/A | M150: =VALUE(L150) -> #N/A | N150: =L150/$L$151 -> #N/A | O150: =D150*N150 -> #N/A
I151: Total Midpoint % Cover: | L151: =SUMIF(L10:L150,">=0") -> 149

Sheet Forbs
A1: DAKOTA COUNTY VEGETATION DATA SHEET
A2: Releve Name:
A3: Surveyor's Name:
A4: MN County:
A5: Date:
A6: GPS:
A7: Plant Community:
A9: Scientific Name | B9: Common Name | C9: --> | D9: C Value | E9: Physiognamy | F9: MN Nativity | G9: MNWI | H9: Rarity Status | I9: ID | J9: CC | K9: CC Range | L9: --> | M9: Midpoint CC | N9: p | O9: pC
A10: Sanicula odorata | B10: =IF(LEN(VLOOKUP(A10,'Species List'!$A:$G,2,FALSE))=0,"",VLOOKUP(A10,'Species List'!$A:$G,2,FALSE)) -> gregarious black snakeroot | C10: =IF(LEN(VLOOKUP(A10,'Species List'!$A:$G,3,FALSE))=0,"",VLOOKUP(A10,'Species List'!$A:$G,3,FALSE)) -> 3 | D10: =VALUE(C10) -> 3 | E10: =IF(LEN(VLOOKUP(A10,'Species List'!$A:$G,4,FALSE))=0,"",VLOOKUP(A10,'Species List'!$A:$G,4,FALSE)) -> H | F10: =IF(LEN(VLOOKUP(A10,'Species List'!$A:$G,5,FALSE))=0,"",VLOOKUP(A10,'Species List'!$A:$G,5,FALSE)) -> Native | G10: =IF(LEN(VLOOKUP(A10,'Species List'!$A:$G,6,FALSE))=0,"",VLOOKUP(A10,'Species List'!$A:$G,6,FALSE)) -> [FAC+] | H10: =VLOOKUP(A10,'Species List'!$A:$G,7,FALSE) -> 0 | J10: 3 | K10: =VLOOKUP(J10,'Species List'!$H$1:$J$9,2,FALSE) -> >25-50% | L10: =VLOOKUP(K10,'Species List'!$I$1:$N$8,2,FALSE) -> 37.5 | M10: =VALUE(L10) -> 37.5 | N10: =L10/$L$150 -> 0.2027027 | O10: =D10*N10 -> 0.60810811
A11: Athyrium filix-femina | B11: =IF(LEN(VLOOKUP(A11,'Species List'!$A:$G,2,FALSE))=0,"",VLOOKUP(A11,'Species List'!$A:$G,2,FALSE)) -> lady fern | C11: =IF(LEN(VLOOKUP(A11,'Species List'!$A:$G,3,FALSE))=0,"",VLOOKUP(A11,'Species List'!$A:$G,3,FALSE)) -> 5 | D11: =VALUE(C11) -> 5 | E11: =IF(LEN(VLOOKUP(A11,'Species List'!$A:$G,4,FALSE))=0,"",VLOOKUP(A11,'Species List'!$A:$G,4,FALSE)) -> H | F11: =IF(LEN(VLOOKUP(A11,'Species List'!$A:$G,5,FALSE))=0,"",VLOOKUP(A11,'Species List'!$A:$G,5,FALSE)) -> Native | G11: =IF(LEN(VLOOKUP(A11,'Species List'!$A:$G,6,FALSE))=0,"",VLOOKUP(A11,'Species List'!$A:$G,6,FALSE)) | H11: =VLOOKUP(A11,'Species List'!$A:$G,7,FALSE) -> 0 | J11: 2 | K11: =VLOOKUP(J11,'Species List'!$H$1:$J$9,2,FALSE) -> >5-25% | L11: =VLOOKUP(K11,'Species List'!$I$1:$N$8,2,FALSE) -> 15 | M11: =VALUE(L11) -> 15 | N11: =L11/$L$150 -> 0.081081081 | O11: =D11*N11 -> 0.40540541
A12: Viola pubescens | B12: =IF(LEN(VLOOKUP(A12,'Species List'!$A:$G,2,FALSE))=0,"",VLOOKUP(A12,'Species List'!$A:$G,2,FALSE)) -> yellow violet | C12: =IF(LEN(VLOOKUP(A12,'Species List'!$A:$G,3,FALSE))=0,"",VLOOKUP(A12,'Species List'!$A:$G,3,FALSE)) -> 4 | D12: =VALUE(C12) -> 4 | E12: =IF(LEN(VLOOKUP(A12,'Species List'!$A:$G,4,FALSE))=0,"",VLOOKUP(A12,'Species List'!$A:$G,4,FALSE)) -> H | F12: =IF(LEN(VLOOKUP(A12,'Species List'!$A:$G,5,FALSE))=0,"",VLOOKUP(A12,'Species List'!$A:$G,5,FALSE)) -> Native | G12: =IF(LEN(VLOOKUP(A12,'Species List'!$A:$G,6,FALSE))=0,"",VLOOKUP(A12,'Species List'!$A:$G,6,FALSE)) -> FACU- | H12: =VLOOKUP(A12,'Species List'!$A:$G,7,FALSE) -> 0 | J12: + | K12: =VLOOKUP(J12,'Species List'!$H$1:$J$9,2,FALSE) -> >1-5% | L12: =VLOOKUP(K12,'Species List'!$I$1:$N$8,2,FALSE) -> 3 | M12: =VALUE(L12) -> 3 | N12: =L12/$L$150 -> 0.016216216 | O12: =D12*N12 -> 0.064864865
A13: Impatiens sp. | B13: =IF(LEN(VLOOKUP(A13,'Species List'!$A:$G,2,FALSE))=0,"",VLOOKUP(A13,'Species List'!$A:$G,2,FALSE)) | C13: =IF(LEN(VLOOKUP(A13,'Species List'!$A:$G,3,FALSE))=0,"",VLOOKUP(A13,'Species List'!$A:$G,3,FALSE)) -> 2 | D13: =VALUE(C13) -> 2 | E13: =IF(LEN(VLOOKUP(A13,'Species List'!$A:$G,4,FALSE))=0,"",VLOOKUP(A13,'Species List'!$A:$G,4,FALSE)) -> H | F13: =IF(LEN(VLOOKUP(A13,'Species List'!$A:$G,5,FALSE))=0,"",VLOOKUP(A13,'Species List'!$A:$G,5,FALSE)) -> Native | G13: =IF(LEN(VLOOKUP(A13,'Species List'!$A:$G,6,FALSE))=0,"",VLOOKUP(A13,'Species List'!$A:$G,6,FALSE)) | H13: =VLOOKUP(A13,'Species List'!$A:$G,7,FALSE) -> 0 | J13: 2 | K13: =VLOOKUP(J13,'Species List'!$H$1:$J$9,2,FALSE) -> >5-25% | L13: =VLOOKUP(K13,'Species List'!$I$1:$N$8,2,FALSE) -> 15 | M13: =VALUE(L13) -> 15 | N13: =L13/$L$150 -> 0.081081081 | O13: =D13*N13 -> 0.16216216
A14: Galium aparine | B14: =IF(LEN(VLOOKUP(A14,'Species List'!$A:$G,2,FALSE))=0,"",VLOOKUP(A14,'Species List'!$A:$G,2,FALSE)) -> cleavers | C14: =IF(LEN(VLOOKUP(A14,'Species List'!$A:$G,3,FALSE))=0,"",VLOOKUP(A14,'Species List'!$A:$G,3,FALSE)) -> 1 | D14: =VALUE(C14) -> 1 | E14: =IF(LEN(VLOOKUP(A14,'Species List'!$A:$G,4,FALSE))=0,"",VLOOKUP(A14,'Species List'!$A:$G,4,FALSE)) -> H | F14: =IF(LEN(VLOOKUP(A14,'Species List'!$A:$G,5,FALSE))=0,"",VLOOKUP(A14,'Species List'!$A:$G,5,FALSE)) -> Native | G14: =IF(LEN(VLOOKUP(A14,'Species List'!$A:$G,6,FALSE))=0,"",VLOOKUP(A14,'Species List'!$A:$G,6,FALSE)) -> FACU | H14: =VLOOKUP(A14,'Species List'!$A:$G,7,FALSE) -> 0 | J14: 1 | K14: =VLOOKUP(J14,'Species List'!$H$1:$J$9,2,FALSE) -> >1-5% | L14: =VLOOKUP(K14,'Species List'!$I$1:$N$8,2,FALSE) -> 3 | M14: =VALUE(L14) -> 3 | N14: =L14/$L$150 -> 0.016216216 | O14: =D14*N14 -> 0.016216216
A15: Caulophyllum thalictroides | B15: =IF(LEN(VLOOKUP(A15,'Species List'!$A:$G,2,FALSE))=0,"",VLOOKUP(A15,'Species List'!$A:$G,2,FALSE)) -> blue cohosh | C15: =IF(LEN(VLOOKUP(A15,'Species List'!$A:$G,3,FALSE))=0,"",VLOOKUP(A15,'Species List'!$A:$G,3,FALSE)) -> 8 | D15: =VALUE(C15) -> 8 | E15: =IF(LEN(VLOOKUP(A15,'Species List'!$A:$G,4,FALSE))=0,"",VLOOKUP(A15,'Species List'!$A:$G,4,FALSE)) -> H | F15: =IF(LEN(VLOOKUP(A15,'Species List'!$A:$G,5,FALSE))=0,"",VLOOKUP(A15,'Species List'!$A:$G,5,FALSE)) -> Native | G15: =IF(LEN(VLOOKUP(A15,'Species List'!$A:$G,6,FALSE))=0,"",VLOOKUP(A15,'Species List'!$A:$G,6,FALSE)) | H15: =VLOOKUP(A15,'Species List'!$A:$G,7,FALSE) -> 0 | J15: 3 | K15: =VLOOKUP(J15,'Species List'!$H$1:$J$9,2,FALSE) -> >25-50% | L15: =VLOOKUP(K15,'Species List'!$I$1:$N$8,2,FALSE) -> 37.5 | M15: =VALUE(L15) -> 37.5 | N15: =L15/$L$150 -> 0.2027027 | O15: =D15*N15 -> 1.6216216
A16: Osmorhiza claytonii | B16: =IF(LEN(VLOOKUP(A16,'Species List'!$A:$G,2,FALSE))=0,"",VLOOKUP(A16,'Species List'!$A:$G,2,FALSE)) -> Clayton's sweet cicely | C16: =IF(LEN(VLOOKUP(A16,'Species List'!$A:$G,3,FALSE))=0,"",VLOOKUP(A16,'Species List'!$A:$G,3,FALSE)) -> 3 | D16: =VALUE(C16) -> 3 | E16: =IF(LEN(VLOOKUP(A16,'Species List'!$A:$G,4,FALSE))=0,"",VLOOKUP(A16,'Species List'!$A:$G,4,FALSE)) -> H | F16: =IF(LEN(VLOOKUP(A16,'Species List'!$A:$G,5,FALSE))=0,"",VLOOKUP(A16,'Species List'!$A:$G,5,FALSE)) -> Native | G16: =IF(LEN(VLOOKUP(A16,'Species List'!$A:$G,6,FALSE))=0,"",VLOOKUP(A16,'Species List'!$A:$G,6,FALSE)) -> FACU- | H16: =VLOOKUP(A16,'Species List'!$A:$G,7,FALSE) -> 0 | J16: 2 | K16: =VLOOKUP(J16,'Species List'!$H$1:$J$9,2,FALSE) -> >5-25% | L16: =VLOOKUP(K16,'Species List'!$I$1:$N$8,2,FALSE) -> 15 | M16: =VALUE(L16) -> 15 | N16: =L16/$L$150 -> 0.081081081 | O16: =D16*N16 -> 0.24324324
A17: Desmodium glutinosum | B17: =IF(LEN(VLOOKUP(A17,'Species List'!$A:$G,2,FALSE))=0,"",VLOOKUP(A17,'Species List'!$A:$G,2,FALSE)) -> pointed-leaved tick trefoil | C17: =IF(LEN(VLOOKUP(A17,'Species List'!$A:$G,3,FALSE))=0,"",VLOOKUP(A17,'Species List'!$A:$G,3,FALSE)) -> 6 | D17: =VALUE(C17) -> 6 | E17: =IF(LEN(VLOOKUP(A17,'Species List'!$A:$G,4,FALSE))=0,"",VLOOKUP(A17,'Species List'!$A:$G,4,FALSE)) -> H | F17: =IF(LEN(VLOOKUP(A17,'Species List'!$A:$G,5,FALSE))=0,"",VLOOKUP(A17,'Species List'!$A:$G,5,FALSE)) -> Native | G17: =IF(LEN(VLOOKUP(A17,'Species List'!$A:$G,6,FALSE))=0,"",VLOOKUP(A17,'Species List'!$A:$G,6,FALSE)) | H17: =VLOOKUP(A17,'Species List'!$A:$G,7,FALSE) -> 0 | J17: 1 | K17: =VLOOKUP(J17,'Species List'!$H$1:$J$9,2,FALSE) -> >1-5% | L17: =VLOOKUP(K17,'Species List'!$I$1:$N$8,2,FALSE) -> 3 | M17: =VALUE(L17) -> 3 | N17: =L17/$L$150 -> 0.016216216 | O17: =D17*N17 -> 0.097297297
A18: Circaea lutetiana | B18: =IF(LEN(VLOOKUP(A18,'Species List'!$A:$G,2,FALSE))=0,"",VLOOKUP(A18,'Species List'!$A:$G,2,FALSE)) -> common enchanter's nightshade | C18: =IF(LEN(VLOOKUP(A18,'Species List'!$A:$G,3,FALSE))=0,"",VLOOKUP(A18,'Species List'!$A:$G,3,FALSE)) -> 2 | D18: =VALUE(C18) -> 2 | E18: =IF(LEN(VLOOKUP(A18,'Species List'!$A:$G,4,FALSE))=0,"",VLOOKUP(A18,'Species List'!$A:$G,4,FALSE)) -> H | F18: =IF(LEN(VLOOKUP(A18,'Species List'!$A:$G,5,FALSE))=0,"",VLOOKUP(A18,'Species List'!$A:$G,5,FALSE)) -> Native | G18: =IF(LEN(VLOOKUP(A18,'Species List'!$A:$G,6,FALSE))=0,"",VLOOKUP(A18,'Species List'!$A:$G,6,FALSE)) -> [FACU] | H18: =VLOOKUP(A18,'Species List'!$A:$G,7,FALSE) -> 0 | J18: 1 | K18: =VLOOKUP(J18,'Species List'!$H$1:$J$9,2,FALSE) -> >1-5% | L18: =VLOOKUP(K18,'Species List'!$I$1:$N$8,2,FALSE) -> 3 | M18: =VALUE(L18) -> 3 | N18: =L18/$L$150 -> 0.016216216 | O18: =D18*N18 -> 0.032432432
A19: Ranunculus recurvatus | B19: =IF(LEN(VLOOKUP(A19,'Species List'!$A:$G,2,FALSE))=0,"",VLOOKUP(A19,'Species List'!$A:$G,2,FALSE)) | C19: =IF(LEN(VLOOKUP(A19,'Species List'!$A:$G,3,FALSE))=0,"",VLOOKUP(A19,'Species List'!$A:$G,3,FALSE)) -> 5 | D19: =VALUE(C19) -> 5 | E19: =IF(LEN(VLOOKUP(A19,'Species List'!$A:$G,4,FALSE))=0,"",VLOOKUP(A19,'Species List'!$A:$G,4,FALSE)) -> H | F19: =IF(LEN(VLOOKUP(A19,'Species List'!$A:$G,5,FALSE))=0,"",VLOOKUP(A19,'Species List'!$A:$G,5,FALSE)) -> Native | G19: =IF(LEN(VLOOKUP(A19,'Species List'!$A:$G,6,FALSE))=0,"",VLOOKUP(A19,'Species List'!$A:$G,6,FALSE)) -> FACW | H19: =VLOOKUP(A19,'Species List'!$A:$G,7,FALSE) -> 0 | J19: + | K19: =VLOOKUP(J19,'Species List'!$H$1:$J$9,2,FALSE) -> >1-5% | L19: =VLOOKUP(K19,'Species List'!$I$1:$N$8,2,FALSE) -> 3 | M19: =VALUE(L19) -> 3 | N19: =L19/$L$150 -> 0.016216216 | O19: =D19*N19 -> 0.081081081
A20: Cryptotaenia canadensis | B20: =IF(LEN(VLOOKUP(A20,'Species List'!$A:$G,2,FALSE))=0,"",VLOOKUP(A20,'Species List'!$A:$G,2,FALSE)) -> honewort | C20: =IF(LEN(VLOOKUP(A20,'Species List'!$A:$G,3,FALSE))=0,"",VLOOKUP(A20,'Species List'!$A:$G,3,FALSE)) -> 3 | D20: =VALUE(C20) -> 3 | E20: =IF(LEN(VLOOKUP(A20,'Species List'!$A:$G,4,FALSE))=0,"",VLOOKUP(A20,'Species List'!$A:$G,4,FALSE)) -> H | F20: =IF(LEN(VLOOKUP(A20,'Species List'!$A:$G,5,FALSE))=0,"",VLOOKUP(A20,'Species List'!$A:$G,5,FALSE)) -> Native | G20: =IF(LEN(VLOOKUP(A20,'Species List'!$A:$G,6,FALSE))=0,"",VLOOKUP(A20,'Species List'!$A:$G,6,FALSE)) -> FAC | H20: =VLOOKUP(A20,'Species List'!$A:$G,7,FALSE) -> 0 | J20: 1 | K20: =VLOOKUP(J20,'Species List'!$H$1:$J$9,2,FALSE) -> >1-5% | L20: =VLOOKUP(K20,'Species List'!$I$1:$N$8,2,FALSE) -> 3 | M20: =VALUE(L20) -> 3 | N20: =L20/$L$150 -> 0.016216216 | O20: =D20*N20 -> 0.048648649
A21: Galium concinnum | B21: =IF(LEN(VLOOKUP(A21,'Species List'!$A:$G,2,FALSE))=0,"",VLOOKUP(A21,'Species List'!$A:$G,2,FALSE)) -> shining bedstraw | C21: =IF(LEN(VLOOKUP(A21,'Species List'!$A:$G,3,FALSE))=0,"",VLOOKUP(A21,'Species List'!$A:$G,3,FALSE)) -> 5 | D21: =VALUE(C21) -> 5 | E21: =IF(LEN(VLOOKUP(A21,'Species List'!$A:$G,4,FALSE))=0,"",VLOOKUP(A21,'Species List'!$A:$G,4,FALSE)) -> H | F21: =IF(LEN(VLOOKUP(A21,'Species List'!$A:$G,5,FALSE))=0,"",VLOOKUP(A21,'Species List'!$A:$G,5,FALSE)) -> Native | G21: =IF(LEN(VLOOKUP(A21,'Species List'!$A:$G,6,FALSE))=0,"",VLOOKUP(A21,'Species List'!$A:$G,6,FALSE)) -> FACU | H21: =VLOOKUP(A21,'Species List'!$A:$G,7,FALSE) -> 0 | J21: + | K21: =VLOOKUP(J21,'Species List'!$H$1:$J$9,2,FALSE) -> >1-5% | L21: =VLOOKUP(K21,'Species List'!$I$1:$N$8,2,FALSE) -> 3 | M21: =VALUE(L21) -> 3 | N21: =L21/$L$150 -> 0.016216216 | O21: =D21*N21 -> 0.081081081
A22: Hackelia virginiana | B22: =IF(LEN(VLOOKUP(A22,'Species List'!$A:$G,2,FALSE))=0,"",VLOOKUP(A22,'Species List'!$A:$G,2,FALSE)) -> Virginia stickseed | C22: =IF(LEN(VLOOKUP(A22,'Species List'!$A:$G,3,FALSE))=0,"",VLOOKUP(A22,'Species List'!$A:$G,3,FALSE)) -> 1 | D22: =VALUE(C22) -> 1 | E22: =IF(LEN(VLOOKUP(A22,'Species List'!$A:$G,4,FALSE))=0,"",VLOOKUP(A22,'Species List'!$A:$G,4,FALSE)) -> H | F22: =IF(LEN(VLOOKUP(A22,'Species List'!$A:$G,5,FALSE))=0,"",VLOOKUP(A22,'Species List'!$A:$G,5,FALSE)) -> Native | G22: =IF(LEN(VLOOKUP(A22,'Species List'!$A:$G,6,FALSE))=0,"",VLOOKUP(A22,'Species List'!$A:$G,6,FALSE)) -> FAC- | H22: =VLOOKUP(A22,'Species List'!$A:$G,7,FALSE) -> 0 | J22: 1 | K22: =VLOOKUP(J22,'Species List'!$H$1:$J$9,2,FALSE) -> >1-5% | L22: =VLOOKUP(K22,'Species List'!$I$1:$N$8,2,FALSE) -> 3 | M22: =VALUE(L22) -> 3 | N22: =L22/$L$150 -> 0.016216216 | O22: =D22*N22 -> 0.016216216
A23: Thalictrum dioicum | B23: =IF(LEN(VLOOKUP(A23,'Species List'!$A:$G,2,FALSE))=0,"",VLOOKUP(A23,'Species List'!$A:$G,2,FALSE)) -> early meadow-rue | C23: =IF(LEN(VLOOKUP(A23,'Species List'!$A:$G,3,FALSE))=0,"",VLOOKUP(A23,'Species List'!$A:$G,3,FALSE)) -> 5 | D23: =VALUE(C23) -> 5 | E23: =IF(LEN(VLOOKUP(A23,'Species List'!$A:$G,4,FALSE))=0,"",VLOOKUP(A23,'Species List'!$A:$G,4,FALSE)) -> H | F23: =IF(LEN(VLOOKUP(A23,'Species List'!$A:$G,5,FALSE))=0,"",VLOOKUP(A23,'Species List'!$A:$G,5,FALSE)) -> Native | G23: =IF(LEN(VLOOKUP(A23,'Species List'!$A:$G,6,FALSE))=0,"",VLOOKUP(A23,'Species List'!$A:$G,6,FALSE)) -> FACU+ | H23: =VLOOKUP(A23,'Species List'!$A:$G,7,FALSE) -> 0 | J23: 1 | K23: =VLOOKUP(J23,'Species List'!$H$1:$J$9,2,FALSE) -> >1-5% | L23: =VLOOKUP(K23,'Species List'!$I$1:$N$8,2,FALSE) -> 3 | M23: =VALUE(L23) -> 3 | N23: =L23/$L$150 -> 0.016216216 | O23: =D23*N23 -> 0.081081081
A24: Maianthemum racemosum | B24: =IF(LEN(VLOOKUP(A24,'Species List'!$A:$G,2,FALSE))=0,"",VLOOKUP(A24,'Species List'!$A:$G,2,FALSE)) | C24: =IF(LEN(VLOOKUP(A24,'Species List'!$A:$G,3,FALSE))=0,"",VLOOKUP(A24,'Species List'!$A:$G,3,FALSE)) -> 5 | D24: =VALUE(C24) -> 5 | E24: =IF(LEN(VLOOKUP(A24,'Species List'!$A:$G,4,FALSE))=0,"",VLOOKUP(A24,'Species List'!$A:$G,4,FALSE)) -> H | F24: =IF(LEN(VLOOKUP(A24,'Species List'!$A:$G,5,FALSE))=0,"",VLOOKUP(A24,'Species List'!$A:$G,5,FALSE)) -> Native | G24: =IF(LEN(VLOOKUP(A24,'Species List'!$A:$G,6,FALSE))=0,"",VLOOKUP(A24,'Species List'!$A:$G,6,FALSE)) -> FACU | H24: =VLOOKUP(A24,'Species List'!$A:$G,7,FALSE) -> 0 | J24: + | K24: =VLOOKUP(J24,'Species List'!$H$1:$J$9,2,FALSE) -> >1-5% | L24: =VLOOKUP(K24,'Species List'!$I$1:$N$8,2,FALSE) -> 3 | M24: =VALUE(L24) -> 3 | N24: =L24/$L$150 -> 0.016216216 | O24: =D24*N24 -> 0.081081081
A25: Phryma leptostachya | B25: =IF(LEN(VLOOKUP(A25,'Species List'!$A:$G,2,FALSE))=0,"",VLOOKUP(A25,'Species List'!$A:$G,2,FALSE)) -> lopseed | C25: =IF(LEN(VLOOKUP(A25,'Species List'!$A:$G,3,FALSE))=0,"",VLOOKUP(A25,'Species List'!$A:$G,3,FALSE)) -> 5 | D25: =VALUE(C25) -> 5 | E25: =IF(LEN(VLOOKUP(A25,'Species List'!$A:$G,4,FALSE))=0,"",VLOOKUP(A25,'Species List'!$A:$G,4,FALSE)) -> H | F25: =IF(LEN(VLOOKUP(A25,'Species List'!$A:$G,5,FALSE))=0,"",VLOOKUP(A25,'Species List'!$A:$G,5,FALSE)) -> Native | G25: =IF(LEN(VLOOKUP(A25,'Species List'!$A:$G,6,FALSE))=0,"",VLOOKUP(A25,'Species List'!$A:$G,6,FALSE)) -> UPL | H25: =VLOOKUP(A25,'Species List'!$A:$G,7,FALSE) -> 0 | J25: + | K25: =VLOOKUP(J25,'Species List'!$H$1:$J$9,2,FALSE) -> >1-5% | L25: =VLOOKUP(K25,'Species List'!$I$1:$N$8,2,FALSE) -> 3 | M25: =VALUE(L25) -> 3 | N25: =L25/$L$150 -> 0.016216216 | O25: =D25*N25 -> 0.081081081
A26: Hydrophyllum virginianum | B26: =IF(LEN(VLOOKUP(A26,'Species List'!$A:$G,2,FALSE))=0,"",VLOOKUP(A26,'Species List'!$A:$G,2,FALSE)) -> Virginia waterleaf | C26: =IF(LEN(VLOOKUP(A26,'Species List'!$A:$G,3,FALSE))=0,"",VLOOKUP(A26,'Species List'!$A:$G,3,FALSE)) -> 3 | D26: =VALUE(C26) -> 3 | E26: =IF(LEN(VLOOKUP(A26,'Species List'!$A:$G,4,FALSE))=0,"",VLOOKUP(A26,'Species List'!$A:$G,4,FALSE)) -> H | F26: =IF(LEN(VLOOKUP(A26,'Species List'!$A:$G,5,FALSE))=0,"",VLOOKUP(A26,'Species List'!$A:$G,5,FALSE)) -> Native | G26: =IF(LEN(VLOOKUP(A26,'Species List'!$A:$G,6,FALSE))=0,"",VLOOKUP(A26,'Species List'!$A:$G,6,FALSE)) -> FACW- | H26: =VLOOKUP(A26,'Species List'!$A:$G,7,FALSE) -> 0 | J26: 1 | K26: =VLOOKUP(J26,'Species List'!$H$1:$J$9,2,FALSE) -> >1-5% | L26: =VLOOKUP(K26,'Species List'!$I$1:$N$8,2,FALSE) -> 3 | M26: =VALUE(L26) -> 3 | N26: =L26/$L$150 -> 0.016216216 | O26: =D26*N26 -> 0.048648649
A27: Arisaema triphyllum | B27: =IF(LEN(VLOOKUP(A27,'Species List'!$A:$G,2,FALSE))=0,"",VLOOKUP(A27,'Species List'!$A:$G,2,FALSE)) -> Jack-in-the-pulpit | C27: =IF(LEN(VLOOKUP(A27,'Species List'!$A:$G,3,FALSE))=0,"",VLOOKUP(A27,'Species List'!$A:$G,3,FALSE)) -> 4 | D27: =VALUE(C27) -> 4 | E27: =IF(LEN(VLOOKUP(A27,'Species List'!$A:$G,4,FALSE))=0,"",VLOOKUP(A27,'Species List'!$A:$G,4,FALSE)) -> H | F27: =IF(LEN(VLOOKUP(A27,'Species List'!$A:$G,5,FALSE))=0,"",VLOOKUP(A27,'Species List'!$A:$G,5,FALSE)) -> Native | G27: =IF(LEN(VLOOKUP(A27,'Species List'!$A:$G,6,FALSE))=0,"",VLOOKUP(A27,'Species List'!$A:$G,6,FALSE)) -> FACW- | H27: =VLOOKUP(A27,'Species List'!$A:$G,7,FALSE) -> 0 | J27: + | K27: =VLOOKUP(J27,'Species List'!$H$1:$J$9,2,FALSE) -> >1-5% | L27: =VLOOKUP(K27,'Species List'!$I$1:$N$8,2,FALSE) -> 3 | M27: =VALUE(L27) -> 3 | N27: =L27/$L$150 -> 0.016216216 | O27: =D27*N27 -> 0.064864865
A28: Lactuca biennis | B28: =IF(LEN(VLOOKUP(A28,'Species List'!$A:$G,2,FALSE))=0,"",VLOOKUP(A28,'Species List'!$A:$G,2,FALSE)) -> biennial blue lettuce | C28: =IF(LEN(VLOOKUP(A28,'Species List'!$A:$G,3,FALSE))=0,"",VLOOKUP(A28,'Species List'!$A:$G,3,FALSE)) -> 3 | D28: =VALUE(C28) -> 3 | E28: =IF(LEN(VLOOKUP(A28,'Species List'!$A:$G,4,FALSE))=0,"",VLOOKUP(A28,'Species List'!$A:$G,4,FALSE)) -> H | F28: =IF(LEN(VLOOKUP(A28,'Species List'!$A:$G,5,FALSE))=0,"",VLOOKUP(A28,'Species List'!$A:$G,5,FALSE)) -> Native | G28: =IF(LEN(VLOOKUP(A28,'Species List'!$A:$G,6,FALSE))=0,"",VLOOKUP(A28,'Species List'!$A:$G,6,FALSE)) -> FAC | H28: =VLOOKUP(A28,'Species List'!$A:$G,7,FALSE) -> 0 | J28: + | K28: =VLOOKUP(J28,'Species List'!$H$1:$J$9,2,FALSE) -> >1-5% | L28: =VLOOKUP(K28,'Species List'!$I$1:$N$8,2,FALSE) -> 3 | M28: =VALUE(L28) -> 3 | N28: =L28/$L$150 -> 0.016216216 | O28: =D28*N28 -> 0.048648649
A29: Galium asprellum | B29: =IF(LEN(VLOOKUP(A29,'Species List'!$A:$G,2,FALSE))=0,"",VLOOKUP(A29,'Species List'!$A:$G,2,FALSE)) -> rough bedstraw | C29: =IF(LEN(VLOOKUP(A29,'Species List'!$A:$G,3,FALSE))=0,"",VLOOKUP(A29,'Species List'!$A:$G,3,FALSE)) -> 6 | D29: =VALUE(C29) -> 6 | E29: =IF(LEN(VLOOKUP(A29,'Species List'!$A:$G,4,FALSE))=0,"",VLOOKUP(A29,'Species List'!$A:$G,4,FALSE)) -> H | F29: =IF(LEN(VLOOKUP(A29,'Species List'!$A:$G,5,FALSE))=0,"",VLOOKUP(A29,'Species List'!$A:$G,5,FALSE)) -> Native | G29: =IF(LEN(VLOOKUP(A29,'Species List'!$A:$G,6,FALSE))=0,"",VLOOKUP(A29,'Species List'!$A:$G,6,FALSE)) -> OBL | H29: =VLOOKUP(A29,'Species List'!$A:$G,7,FALSE) -> 0 | J29: + | K29: =VLOOKUP(J29,'Species List'!$H$1:$J$9,2,FALSE) -> >1-5% | L29: =VLOOKUP(K29,'Species List'!$I$1:$N$8,2,FALSE) -> 3 | M29: =VALUE(L29) -> 3 | N29: =L29/$L$150 -> 0.016216216 | O29: =D29*N29 -> 0.097297297
A30: Thalictrum dasycarpum | B30: =IF(LEN(VLOOKUP(A30,'Species List'!$A:$G,2,FALSE))=0,"",VLOOKUP(A30,'Species List'!$A:$G,2,FALSE)) -> tall meadow-rue | C30: =IF(LEN(VLOOKUP(A30,'Species List'!$A:$G,3,FALSE))=0,"",VLOOKUP(A30,'Species List'!$A:$G,3,FALSE)) -> 4 | D30: =VALUE(C30) -> 4 | E30: =IF(LEN(VLOOKUP(A30,'Species List'!$A:$G,4,FALSE))=0,"",VLOOKUP(A30,'Species List'!$A:$G,4,FALSE)) -> H | F30: =IF(LEN(VLOOKUP(A30,'Species List'!$A:$G,5,FALSE))=0,"",VLOOKUP(A30,'Species List'!$A:$G,5,FALSE)) -> Native | G30: =IF(LEN(VLOOKUP(A30,'Species List'!$A:$G,6,FALSE))=0,"",VLOOKUP(A30,'Species List'!$A:$G,6,FALSE)) -> FACW- | H30: =VLOOKUP(A30,'Species List'!$A:$G,7,FALSE) -> 0 | J30: + | K30: =VLOOKUP(J30,'Species List'!$H$1:$J$9,2,FALSE) -> >1-5% | L30: =VLOOKUP(K30,'Species List'!$I$1:$N$8,2,FALSE) -> 3 | M30: =VALUE(L30) -> 3 | N30: =L30/$L$150 -> 0.016216216 | O30: =D30*N30 -> 0.064864865
A31: Polygonatum biflorum | B31: =IF(LEN(VLOOKUP(A31,'Species List'!$A:$G,2,FALSE))=0,"",VLOOKUP(A31,'Species List'!$A:$G,2,FALSE)) -> giant Solomon's seal | C31: =IF(LEN(VLOOKUP(A31,'Species List'!$A:$G,3,FALSE))=0,"",VLOOKUP(A31,'Species List'!$A:$G,3,FALSE)) -> 4 | D31: =VALUE(C31) -> 4 | E31: =IF(LEN(VLOOKUP(A31,'Species List'!$A:$G,4,FALSE))=0,"",VLOOKUP(A31,'Species List'!$A:$G,4,FALSE)) -> H | F31: =IF(LEN(VLOOKUP(A31,'Species List'!$A:$G,5,FALSE))=0,"",VLOOKUP(A31,'Species List'!$A:$G,5,FALSE)) -> Native | G31: =IF(LEN(VLOOKUP(A31,'Species List'!$A:$G,6,FALSE))=0,"",VLOOKUP(A31,'Species List'!$A:$G,6,FALSE)) -> [FACU] | H31: =VLOOKUP(A31,'Species List'!$A:$G,7,FALSE) -> 0 | J31: r | K31: =VLOOKUP(J31,'Species List'!$H$1:$J$9,2,FALSE) -> >0-1% | L31: =VLOOKUP(K31,'Species List'!$I$1:$N$8,2,FALSE) -> 0.5 | M31: =VALUE(L31) -> 0.5 | N31: =L31/$L$150 -> 0.0027027027 | O31: =D31*N31 -> 0.010810811
A32: Symphyotrichum ontarionis | B32: =IF(LEN(VLOOKUP(A32,'Species List'!$A:$G,2,FALSE))=0,"",VLOOKUP(A32,'Species List'!$A:$G,2,FALSE)) | C32: =IF(LEN(VLOOKUP(A32,'Species List'!$A:$G,3,FALSE))=0,"",VLOOKUP(A32,'Species List'!$A:$G,3,FALSE)) -> 6 | D32: =VALUE(C32) -> 6 | E32: =IF(LEN(VLOOKUP(A32,'Species List'!$A:$G,4,FALSE))=0,"",VLOOKUP(A32,'Species List'!$A:$G,4,FALSE)) -> H | F32: =IF(LEN(VLOOKUP(A32,'Species List'!$A:$G,5,FALSE))=0,"",VLOOKUP(A32,'Species List'!$A:$G,5,FALSE)) -> Native | G32: =IF(LEN(VLOOKUP(A32,'Species List'!$A:$G,6,FALSE))=0,"",VLOOKUP(A32,'Species List'!$A:$G,6,FALSE)) -> FAC | H32: =VLOOKUP(A32,'Species List'!$A:$G,7,FALSE) -> 0 | J32: + | K32: =VLOOKUP(J32,'Species List'!$H$1:$J$9,2,FALSE) -> >1-5% | L32: =VLOOKUP(K32,'Species List'!$I$1:$N$8,2,FALSE) -> 3 | M32: =VALUE(L32) -> 3 | N32: =L32/$L$150 -> 0.016216216 | O32: =D32*N32 -> 0.097297297
A33: Amphicarpaea bracteata | B33: =IF(LEN(VLOOKUP(A33,'Species List'!$A:$G,2,FALSE))=0,"",VLOOKUP(A33,'Species List'!$A:$G,2,FALSE)) -> hog peanut | C33: =IF(LEN(VLOOKUP(A33,'Species List'!$A:$G,3,FALSE))=0,"",VLOOKUP(A33,'Species List'!$A:$G,3,FALSE)) -> 2 | D33: =VALUE(C33) -> 2 | E33: =IF(LEN(VLOOKUP(A33,'Species List'!$A:$G,4,FALSE))=0,"",VLOOKUP(A33,'Species List'!$A:$G,4,FALSE)) -> H | F33: =IF(LEN(VLOOKUP(A33,'Species List'!$A:$G,5,FALSE))=0,"",VLOOKUP(A33,'Species List'!$A:$G,5,FALSE)) -> Native | G33: =IF(LEN(VLOOKUP(A33,'Species List'!$A:$G,6,FALSE))=0,"",VLOOKUP(A33,'Species List'!$A:$G,6,FALSE)) -> FAC | H33: =VLOOKUP(A33,'Species List'!$A:$G,7,FALSE) -> 0 | J33: + | K33: =VLOOKUP(J33,'Species List'!$H$1:$J$9,2,FALSE) -> >1-5% | L33: =VLOOKUP(K33,'Species List'!$I$1:$N$8,2,FALSE) -> 3 | M33: =VALUE(L33) -> 3 | N33: =L33/$L$150 -> 0.016216216 | O33: =D33*N33 -> 0.032432432
A34: Geranium maculatum | B34: =IF(LEN(VLOOKUP(A34,'Species List'!$A:$G,2,FALSE))=0,"",VLOOKUP(A34,'Species List'!$A:$G,2,FALSE)) -> wild geranium | C34: =IF(LEN(VLOOKUP(A34,'Species List'!$A:$G,3,FALSE))=0,"",VLOOKUP(A34,'Species List'!$A:$G,3,FALSE)) -> 4 | D34: =VALUE(C34) -> 4 | E34: =IF(LEN(VLOOKUP(A34,'Species List'!$A:$G,4,FALSE))=0,"",VLOOKUP(A34,'Species List'!$A:$G,4,FALSE)) -> H | F34: =IF(LEN(VLOOKUP(A34,'Species List'!$A:$G,5,FALSE))=0,"",VLOOKUP(A34,'Species List'!$A:$G,5,FALSE)) -> Native | G34: =IF(LEN(VLOOKUP(A34,'Species List'!$A:$G,6,FALSE))=0,"",VLOOKUP(A34,'Species List'!$A:$G,6,FALSE)) -> FACU | H34: =VLOOKUP(A34,'Species List'!$A:$G,7,FALSE) -> 0 | J34: + | K34: =VLOOKUP(J34,'Species List'!$H$1:$J$9,2,FALSE) -> >1-5% | L34: =VLOOKUP(K34,'Species List'!$I$1:$N$8,2,FALSE) -> 3 | M34: =VALUE(L34) -> 3 | N34: =L34/$L$150 -> 0.016216216 | O34: =D34*N34 -> 0.064864865
A35: Trillium sp. | B35: =IF(LEN(VLOOKUP(A35,'Species List'!$A:$G,2,FALSE))=0,"",VLOOKUP(A35,'Species List'!$A:$G,2,FALSE)) | C35: =IF(LEN(VLOOKUP(A35,'Species List'!$A:$G,3,FALSE))=0,"",VLOOKUP(A35,'Species List'!$A:$G,3,FALSE)) -> 6 | D35: =VALUE(C35) -> 6 | E35: =IF(LEN(VLOOKUP(A35,'Species List'!$A:$G,4,FALSE))=0,"",VLOOKUP(A35,'Species List'!$A:$G,4,FALSE)) -> H | F35: =IF(LEN(VLOOKUP(A35,'Species List'!$A:$G,5,FALSE))=0,"",VLOOKUP(A35,'Species List'!$A:$G,5,FALSE)) -> Native | G35: =IF(LEN(VLOOKUP(A35,'Species List'!$A:$G,6,FALSE))=0,"",VLOOKUP(A35,'Species List'!$A:$G,6,FALSE)) | H35: =VLOOKUP(A35,'Species List'!$A:$G,7,FALSE) -> 0 | J35: + | K35: =VLOOKUP(J35,'Species List'!$H$1:$J$9,2,FALSE) -> >1-5% | L35: =VLOOKUP(K35,'Species List'!$I$1:$N$8,2,FALSE) -> 3 | M35: =VALUE(L35) -> 3 | N35: =L35/$L$150 -> 0.016216216 | O35: =D35*N35 -> 0.097297297
A36: Urtica dioica | B36: =IF(LEN(VLOOKUP(A36,'Species List'!$A:$G,2,FALSE))=0,"",VLOOKUP(A36,'Species List'!$A:$G,2,FALSE)) | C36: =IF(LEN(VLOOKUP(A36,'Species List'!$A:$G,3,FALSE))=0,"",VLOOKUP(A36,'Species List'!$A:$G,3,FALSE)) -> 1 | D36: =VALUE(C36) -> 1 | E36: =IF(LEN(VLOOKUP(A36,'Species List'!$A:$G,4,FALSE))=0,"",VLOOKUP(A36,'Species List'!$A:$G,4,FALSE)) -> H | F36: =IF(LEN(VLOOKUP(A36,'Species List'!$A:$G,5,FALSE))=0,"",VLOOKUP(A36,'Species List'!$A:$G,5,FALSE)) -> Native | G36: =IF(LEN(VLOOKUP(A36,'Species List'!$A:$G,6,FALSE))=0,"",VLOOKUP(A36,'Species List'!$A:$G,6,FALSE)) -> FACW | H36: =VLOOKUP(A36,'Species List'!$A:$G,7,FALSE) -> 0 | J36: + | K36: =VLOOKUP(J36,'Species List'!$H$1:$J$9,2,FALSE) -> >1-5% | L36: =VLOOKUP(K36,'Species List'!$I$1:$N$8,2,FALSE) -> 3 | M36: =VALUE(L36) -> 3 | N36: =L36/$L$150 -> 0.016216216 | O36: =D36*N36 -> 0.016216216
A37: Galium triflorum | B37: =IF(LEN(VLOOKUP(A37,'Species List'!$A:$G,2,FALSE))=0,"",VLOOKUP(A37,'Species List'!$A:$G,2,FALSE)) | C37: =IF(LEN(VLOOKUP(A37,'Species List'!$A:$G,3,FALSE))=0,"",VLOOKUP(A37,'Species List'!$A:$G,3,FALSE)) -> 4 | D37: =VALUE(C37) -> 4 | E37: =IF(LEN(VLOOKUP(A37,'Species List'!$A:$G,4,FALSE))=0,"",VLOOKUP(A37,'Species List'!$A:$G,4,FALSE)) -> H | F37: =IF(LEN(VLOOKUP(A37,'Species List'!$A:$G,5,FALSE))=0,"",VLOOKUP(A37,'Species List'!$A:$G,5,FALSE)) -> Native | G37: =IF(LEN(VLOOKUP(A37,'Species List'!$A:$G,6,FALSE))=0,"",VLOOKUP(A37,'Species List'!$A:$G,6,FALSE)) -> FACU+ | H37: =VLOOKUP(A37,'Species List'!$A:$G,7,FALSE) -> 0 | J37: r | K37: =VLOOKUP(J37,'Species List'!$H$1:$J$9,2,FALSE) -> >0-1% | L37: =VLOOKUP(K37,'Species List'!$I$1:$N$8,2,FALSE) -> 0.5 | M37: =VALUE(L37) -> 0.5 | N37: =L37/$L$150 -> 0.0027027027 | O37: =D37*N37 -> 0.010810811
A38: Arctium minus | B38: =IF(LEN(VLOOKUP(A38,'Species List'!$A:$G,2,FALSE))=0,"",VLOOKUP(A38,'Species List'!$A:$G,2,FALSE)) -> common burdock | C38: =IF(LEN(VLOOKUP(A38,'Species List'!$A:$G,3,FALSE))=0,"",VLOOKUP(A38,'Species List'!$A:$G,3,FALSE)) -> 0 | D38: =VALUE(C38) -> 0 | E38: =IF(LEN(VLOOKUP(A38,'Species List'!$A:$G,4,FALSE))=0,"",VLOOKUP(A38,'Species List'!$A:$G,4,FALSE)) -> H | F38: =IF(LEN(VLOOKUP(A38,'Species List'!$A:$G,5,FALSE))=0,"",VLOOKUP(A38,'Species List'!$A:$G,5,FALSE)) -> Introduced | G38: =IF(LEN(VLOOKUP(A38,'Species List'!$A:$G,6,FALSE))=0,"",VLOOKUP(A38,'Species List'!$A:$G,6,FALSE)) -> FACU | H38: =VLOOKUP(A38,'Species List'!$A:$G,7,FALSE) -> 0 | J38: r | K38: =VLOOKUP(J38,'Species List'!$H$1:$J$9,2,FALSE) -> >0-1% | L38: =VLOOKUP(K38,'Species List'!$I$1:$N$8,2,FALSE) -> 0.5 | M38: =VALUE(L38) -> 0.5 | N38: =L38/$L$150 -> 0.0027027027 | O38: =D38*N38 -> 0
A39: Smilax lasioneura | B39: =IF(LEN(VLOOKUP(A39,'Species List'!$A:$G,2,FALSE))=0,"",VLOOKUP(A39,'Species List'!$A:$G,2,FALSE)) -> common carrion flower | C39: =IF(LEN(VLOOKUP(A39,'Species List'!$A:$G,3,FALSE))=0,"",VLOOKUP(A39,'Species List'!$A:$G,3,FALSE)) -> 4 | D39: =VALUE(C39) -> 4 | E39: =IF(LEN(VLOOKUP(A39,'Species List'!$A:$G,4,FALSE))=0,"",VLOOKUP(A39,'Species List'!$A:$G,4,FALSE)) -> H | F39: =IF(LEN(VLOOKUP(A39,'Species List'!$A:$G,5,FALSE))=0,"",VLOOKUP(A39,'Species List'!$A:$G,5,FALSE)) -> Native | G39: =IF(LEN(VLOOKUP(A39,'Species List'!$A:$G,6,FALSE))=0,"",VLOOKUP(A39,'Species List'!$A:$G,6,FALSE)) | H39: =VLOOKUP(A39,'Species List'!$A:$G,7,FALSE) -> 0 | J39: r | K39: =VLOOKUP(J39,'Species List'!$H$1:$J$9,2,FALSE) -> >0-1% | L39: =VLOOKUP(K39,'Species List'!$I$1:$N$8,2,FALSE) -> 0.5 | M39: =VALUE(L39) -> 0.5 | N39: =L39/$L$150 -> 0.0027027027 | O39: =D39*N39 -> 0.010810811
B40: =IF(LEN(VLOOKUP(A40,'Species List'!$A:$G,2,FALSE))=0,"",VLOOKUP(A40,'Species List'!$A:$G,2,FALSE)) -> #N/A | C40: =IF(LEN(VLOOKUP(A40,'Species List'!$A:$G,3,FALSE))=0,"",VLOOKUP(A40,'Species List'!$A:$G,3,FALSE)) -> #N/A | D40: =VALUE(C40) -> #N/A | E40: =IF(LEN(VLOOKUP(A40,'Species List'!$A:$G,4,FALSE))=0,"",VLOOKUP(A40,'Species List'!$A:$G,4,FALSE)) -> #N/A | F40: =IF(LEN(VLOOKUP(A40,'Species List'!$A:$G,5,FALSE))=0,"",VLOOKUP(A40,'Species List'!$A:$G,5,FALSE)) -> #N/A | G40: =IF(LEN(VLOOKUP(A40,'Species List'!$A:$G,6,FALSE))=0,"",VLOOKUP(A40,'Species List'!$A:$G,6,FALSE)) -> #N/A | H40: =VLOOKUP(A40,'Species List'!$A:$G,7,FALSE) -> #N/A | K40: =VLOOKUP(J40,'Species List'!$H$1:$J$9,2,FALSE) -> #N/A | L40: =VLOOKUP(K40,'Species List'!$I$1:$N$8,2,FALSE) -> #N/A | M40: =VALUE(L40) -> #N/A | N40: =L40/$L$150 -> #N/A | O40: =D40*N40 -> #N/A
B41: =IF(LEN(VLOOKUP(A41,'Species List'!$A:$G,2,FALSE))=0,"",VLOOKUP(A41,'Species List'!$A:$G,2,FALSE)) -> #N/A | C41: =IF(LEN(VLOOKUP(A41,'Species List'!$A:$G,3,FALSE))=0,"",VLOOKUP(A41,'Species List'!$A:$G,3,FALSE)) -> #N/A | D41: =VALUE(C41) -> #N/A | E41: =IF(LEN(VLOOKUP(A41,'Species List'!$A:$G,4,FALSE))=0,"",VLOOKUP(A41,'Species List'!$A:$G,4,FALSE)) -> #N/A | F41: =IF(LEN(VLOOKUP(A41,'Species List'!$A:$G,5,FALSE))=0,"",VLOOKUP(A41,'Species List'!$A:$G,5,FALSE)) -> #N/A | G41: =IF(LEN(VLOOKUP(A41,'Species List'!$A:$G,6,FALSE))=0,"",VLOOKUP(A41,'Species List'!$A:$G,6,FALSE)) -> #N/A | H41: =VLOOKUP(A41,'Species List'!$A:$G,7,FALSE) -> #N/A | K41: =VLOOKUP(J41,'Species List'!$H$1:$J$9,2,FALSE) -> #N/A | L41: =VLOOKUP(K41,'Species List'!$I$1:$N$8,2,FALSE) -> #N/A | M41: =VALUE(L41) -> #N/A | N41: =L41/$L$150 -> #N/A | O41: =D41*N41 -> #N/A
...

Sheet Grasses
A1: DAKOTA COUNTY VEGETATION DATA SHEET
A2: Releve Name:
A3: Surveyor's Name:
A4: MN County:
A5: Date:
A6: GPS:
A7: Plant Community:
A9: Scientific Name | B9: Common Name | C9: --> | D9: C Value | E9: Physiognamy | F9: MN Nativity | G9: MNWI | H9: Rarity Status | I9: ID | J9: CC | K9: CC Range | L9: --> | M9: Midpoint CC | N9: p | O9: pC
A10: Festuca subverticillata | B10: =IF(LEN(VLOOKUP(A10,'Species List'!$A:$G,2,FALSE))=0,"",VLOOKUP(A10,'Species List'!$A:$G,2,FALSE)) -> nodding fescue | C10: =IF(LEN(VLOOKUP(A10,'Species List'!$A:$G,3,FALSE))=0,"",VLOOKUP(A10,'Species List'!$A:$G,3,FALSE)) -> 6 | D10: =VALUE(C10) -> 6 | E10: =IF(LEN(VLOOKUP(A10,'Species List'!$A:$G,4,FALSE))=0,"",VLOOKUP(A10,'Species List'!$A:$G,4,FALSE)) -> G | F10: =IF(LEN(VLOOKUP(A10,'Species List'!$A:$G,5,FALSE))=0,"",VLOOKUP(A10,'Species List'!$A:$G,5,FALSE)) -> Native | G10: =IF(LEN(VLOOKUP(A10,'Species List'!$A:$G,6,FALSE))=0,"",VLOOKUP(A10,'Species List'!$A:$G,6,FALSE)) -> [FACU+] | H10: =VLOOKUP(A10,'Species List'!$A:$G,7,FALSE) -> 0 | J10: 2 | K10: =VLOOKUP(J10,'Species List'!$H$1:$J$9,2,FALSE) -> >5-25% | L10: =VLOOKUP(K10,'Species List'!$I$1:$N$8,2,FALSE) -> 15 | M10: =VALUE(L10) -> 15 | N10: =L10/$L$151 -> 0.49180328 | O10: =D10*N10 -> 2.9508197
